2019-02-22 20:38:07,674 [Thread-14:7380] [django.request:93] [base:get_response] [WARNING]- Not Found: /favicon.ico
2019-02-22 20:38:09,291 [Thread-17:1040] [django.request:118] [exception:handle_uncaught_exception] [ERROR]- Internal Server Error: /project/list/
Traceback (most recent call last):
  File "C:\Python37\lib\site-packages\django\core\handlers\exception.py", line 35, in inner
    response = get_response(request)
  File "C:\Python37\lib\site-packages\django\core\handlers\base.py", line 128, in _get_response
    response = self.process_exception_by_middleware(e, request)
  File "C:\Python37\lib\site-packages\django\core\handlers\base.py", line 126, in _get_response
    response = wrapped_callback(request, *callback_args, **callback_kwargs)
  File "C:\Python37\lib\site-packages\django\views\generic\base.py", line 69, in view
    return self.dispatch(request, *args, **kwargs)
  File "C:\Python37\lib\site-packages\django\views\generic\base.py", line 89, in dispatch
    return handler(request, *args, **kwargs)
  File "C:\Users\Administrator\PycharmProjects\TestPlatformWeb\apps\project\views.py", line 24, in get
    return render(request, 'project.html',{"obj_form":project_from})
  File "C:\Python37\lib\site-packages\django\shortcuts.py", line 36, in render
    content = loader.render_to_string(template_name, context, request, using=using)
  File "C:\Python37\lib\site-packages\django\template\loader.py", line 62, in render_to_string
    return template.render(context, request)
  File "C:\Python37\lib\site-packages\django\template\backends\django.py", line 61, in render
    return self.template.render(context)
  File "C:\Python37\lib\site-packages\django\template\base.py", line 175, in render
    return self._render(context)
  File "C:\Python37\lib\site-packages\django\template\base.py", line 167, in _render
    return self.nodelist.render(context)
  File "C:\Python37\lib\site-packages\django\template\base.py", line 943, in render
    bit = node.render_annotated(context)
  File "C:\Python37\lib\site-packages\django\template\base.py", line 910, in render_annotated
    return self.render(context)
  File "C:\Python37\lib\site-packages\django\template\loader_tags.py", line 155, in render
    return compiled_parent._render(context)
  File "C:\Python37\lib\site-packages\django\template\base.py", line 167, in _render
    return self.nodelist.render(context)
  File "C:\Python37\lib\site-packages\django\template\base.py", line 943, in render
    bit = node.render_annotated(context)
  File "C:\Python37\lib\site-packages\django\template\base.py", line 910, in render_annotated
    return self.render(context)
  File "C:\Python37\lib\site-packages\django\template\loader_tags.py", line 67, in render
    result = block.nodelist.render(context)
  File "C:\Python37\lib\site-packages\django\template\base.py", line 943, in render
    bit = node.render_annotated(context)
  File "C:\Python37\lib\site-packages\django\template\base.py", line 910, in render_annotated
    return self.render(context)
  File "C:\Python37\lib\site-packages\django\template\loader_tags.py", line 67, in render
    result = block.nodelist.render(context)
  File "C:\Python37\lib\site-packages\django\template\base.py", line 943, in render
    bit = node.render_annotated(context)
  File "C:\Python37\lib\site-packages\django\template\base.py", line 910, in render_annotated
    return self.render(context)
  File "C:\Python37\lib\site-packages\django\template\defaulttags.py", line 447, in render
    url = reverse(view_name, args=args, kwargs=kwargs, current_app=current_app)
  File "C:\Python37\lib\site-packages\django\urls\base.py", line 90, in reverse
    return iri_to_uri(resolver._reverse_with_prefix(view, prefix, *args, **kwargs))
  File "C:\Python37\lib\site-packages\django\urls\resolvers.py", line 636, in _reverse_with_prefix
    raise NoReverseMatch(msg)
django.urls.exceptions.NoReverseMatch: Reverse for 'project_detail' with arguments '('',)' not found. 1 pattern(s) tried: ['project/edit/(?P<id>[0-9]+)/$']
2019-02-22 21:06:10,482 [Thread-29:10992] [django.request:118] [exception:handle_uncaught_exception] [ERROR]- Internal Server Error: /project/list/
Traceback (most recent call last):
  File "C:\Python37\lib\site-packages\django\core\handlers\exception.py", line 35, in inner
    response = get_response(request)
  File "C:\Python37\lib\site-packages\django\core\handlers\base.py", line 128, in _get_response
    response = self.process_exception_by_middleware(e, request)
  File "C:\Python37\lib\site-packages\django\core\handlers\base.py", line 126, in _get_response
    response = wrapped_callback(request, *callback_args, **callback_kwargs)
  File "C:\Python37\lib\site-packages\django\views\generic\base.py", line 69, in view
    return self.dispatch(request, *args, **kwargs)
  File "C:\Python37\lib\site-packages\django\views\generic\base.py", line 89, in dispatch
    return handler(request, *args, **kwargs)
  File "C:\Users\Administrator\PycharmProjects\TestPlatformWeb\apps\project\views.py", line 24, in get
    return render(request, 'project.html',{"obj_form":project_from})
  File "C:\Python37\lib\site-packages\django\shortcuts.py", line 36, in render
    content = loader.render_to_string(template_name, context, request, using=using)
  File "C:\Python37\lib\site-packages\django\template\loader.py", line 62, in render_to_string
    return template.render(context, request)
  File "C:\Python37\lib\site-packages\django\template\backends\django.py", line 61, in render
    return self.template.render(context)
  File "C:\Python37\lib\site-packages\django\template\base.py", line 175, in render
    return self._render(context)
  File "C:\Python37\lib\site-packages\django\template\base.py", line 167, in _render
    return self.nodelist.render(context)
  File "C:\Python37\lib\site-packages\django\template\base.py", line 943, in render
    bit = node.render_annotated(context)
  File "C:\Python37\lib\site-packages\django\template\base.py", line 910, in render_annotated
    return self.render(context)
  File "C:\Python37\lib\site-packages\django\template\loader_tags.py", line 155, in render
    return compiled_parent._render(context)
  File "C:\Python37\lib\site-packages\django\template\base.py", line 167, in _render
    return self.nodelist.render(context)
  File "C:\Python37\lib\site-packages\django\template\base.py", line 943, in render
    bit = node.render_annotated(context)
  File "C:\Python37\lib\site-packages\django\template\base.py", line 910, in render_annotated
    return self.render(context)
  File "C:\Python37\lib\site-packages\django\template\loader_tags.py", line 67, in render
    result = block.nodelist.render(context)
  File "C:\Python37\lib\site-packages\django\template\base.py", line 943, in render
    bit = node.render_annotated(context)
  File "C:\Python37\lib\site-packages\django\template\base.py", line 910, in render_annotated
    return self.render(context)
  File "C:\Python37\lib\site-packages\django\template\loader_tags.py", line 67, in render
    result = block.nodelist.render(context)
  File "C:\Python37\lib\site-packages\django\template\base.py", line 943, in render
    bit = node.render_annotated(context)
  File "C:\Python37\lib\site-packages\django\template\base.py", line 910, in render_annotated
    return self.render(context)
  File "C:\Python37\lib\site-packages\django\template\defaulttags.py", line 447, in render
    url = reverse(view_name, args=args, kwargs=kwargs, current_app=current_app)
  File "C:\Python37\lib\site-packages\django\urls\base.py", line 90, in reverse
    return iri_to_uri(resolver._reverse_with_prefix(view, prefix, *args, **kwargs))
  File "C:\Python37\lib\site-packages\django\urls\resolvers.py", line 636, in _reverse_with_prefix
    raise NoReverseMatch(msg)
django.urls.exceptions.NoReverseMatch: Reverse for 'project_detail' with arguments '('',)' not found. 1 pattern(s) tried: ['project/edit/(?P<id>[0-9]+)/$']
2019-02-24 11:56:17,561 [Thread-22:13984] [django.request:93] [base:get_response] [WARNING]- Not Found: /favicon.ico
2019-02-24 12:06:07,655 [Thread-23:11324] [django.request:118] [exception:handle_uncaught_exception] [ERROR]- Internal Server Error: /project/list/
Traceback (most recent call last):
  File "C:\Python37\lib\site-packages\django\core\handlers\exception.py", line 35, in inner
    response = get_response(request)
  File "C:\Python37\lib\site-packages\django\core\handlers\base.py", line 128, in _get_response
    response = self.process_exception_by_middleware(e, request)
  File "C:\Python37\lib\site-packages\django\core\handlers\base.py", line 126, in _get_response
    response = wrapped_callback(request, *callback_args, **callback_kwargs)
  File "C:\Python37\lib\site-packages\django\views\generic\base.py", line 69, in view
    return self.dispatch(request, *args, **kwargs)
  File "C:\Python37\lib\site-packages\django\views\generic\base.py", line 89, in dispatch
    return handler(request, *args, **kwargs)
  File "C:\Users\Administrator\PycharmProjects\TestPlatformWeb\apps\project\views.py", line 24, in get
    return render(request, 'project.html',{"obj_form":project_from})
  File "C:\Python37\lib\site-packages\django\shortcuts.py", line 36, in render
    content = loader.render_to_string(template_name, context, request, using=using)
  File "C:\Python37\lib\site-packages\django\template\loader.py", line 62, in render_to_string
    return template.render(context, request)
  File "C:\Python37\lib\site-packages\django\template\backends\django.py", line 61, in render
    return self.template.render(context)
  File "C:\Python37\lib\site-packages\django\template\base.py", line 175, in render
    return self._render(context)
  File "C:\Python37\lib\site-packages\django\template\base.py", line 167, in _render
    return self.nodelist.render(context)
  File "C:\Python37\lib\site-packages\django\template\base.py", line 943, in render
    bit = node.render_annotated(context)
  File "C:\Python37\lib\site-packages\django\template\base.py", line 910, in render_annotated
    return self.render(context)
  File "C:\Python37\lib\site-packages\django\template\loader_tags.py", line 155, in render
    return compiled_parent._render(context)
  File "C:\Python37\lib\site-packages\django\template\base.py", line 167, in _render
    return self.nodelist.render(context)
  File "C:\Python37\lib\site-packages\django\template\base.py", line 943, in render
    bit = node.render_annotated(context)
  File "C:\Python37\lib\site-packages\django\template\base.py", line 910, in render_annotated
    return self.render(context)
  File "C:\Python37\lib\site-packages\django\template\loader_tags.py", line 67, in render
    result = block.nodelist.render(context)
  File "C:\Python37\lib\site-packages\django\template\base.py", line 943, in render
    bit = node.render_annotated(context)
  File "C:\Python37\lib\site-packages\django\template\base.py", line 910, in render_annotated
    return self.render(context)
  File "C:\Python37\lib\site-packages\django\template\loader_tags.py", line 67, in render
    result = block.nodelist.render(context)
  File "C:\Python37\lib\site-packages\django\template\base.py", line 943, in render
    bit = node.render_annotated(context)
  File "C:\Python37\lib\site-packages\django\template\base.py", line 910, in render_annotated
    return self.render(context)
  File "C:\Python37\lib\site-packages\django\template\defaulttags.py", line 447, in render
    url = reverse(view_name, args=args, kwargs=kwargs, current_app=current_app)
  File "C:\Python37\lib\site-packages\django\urls\base.py", line 90, in reverse
    return iri_to_uri(resolver._reverse_with_prefix(view, prefix, *args, **kwargs))
  File "C:\Python37\lib\site-packages\django\urls\resolvers.py", line 636, in _reverse_with_prefix
    raise NoReverseMatch(msg)
django.urls.exceptions.NoReverseMatch: Reverse for 'project_detail' with arguments '('',)' not found. 1 pattern(s) tried: ['project/edit/(?P<id>[0-9]+)/$']
2019-02-24 12:06:43,264 [Thread-25:13564] [django.request:118] [exception:handle_uncaught_exception] [ERROR]- Internal Server Error: /project/list/
Traceback (most recent call last):
  File "C:\Python37\lib\site-packages\django\core\handlers\exception.py", line 35, in inner
    response = get_response(request)
  File "C:\Python37\lib\site-packages\django\core\handlers\base.py", line 128, in _get_response
    response = self.process_exception_by_middleware(e, request)
  File "C:\Python37\lib\site-packages\django\core\handlers\base.py", line 126, in _get_response
    response = wrapped_callback(request, *callback_args, **callback_kwargs)
  File "C:\Python37\lib\site-packages\django\views\generic\base.py", line 69, in view
    return self.dispatch(request, *args, **kwargs)
  File "C:\Python37\lib\site-packages\django\views\generic\base.py", line 89, in dispatch
    return handler(request, *args, **kwargs)
  File "C:\Users\Administrator\PycharmProjects\TestPlatformWeb\apps\project\views.py", line 24, in get
    return render(request, 'project.html',{"obj_form":project_from})
  File "C:\Python37\lib\site-packages\django\shortcuts.py", line 36, in render
    content = loader.render_to_string(template_name, context, request, using=using)
  File "C:\Python37\lib\site-packages\django\template\loader.py", line 62, in render_to_string
    return template.render(context, request)
  File "C:\Python37\lib\site-packages\django\template\backends\django.py", line 61, in render
    return self.template.render(context)
  File "C:\Python37\lib\site-packages\django\template\base.py", line 175, in render
    return self._render(context)
  File "C:\Python37\lib\site-packages\django\template\base.py", line 167, in _render
    return self.nodelist.render(context)
  File "C:\Python37\lib\site-packages\django\template\base.py", line 943, in render
    bit = node.render_annotated(context)
  File "C:\Python37\lib\site-packages\django\template\base.py", line 910, in render_annotated
    return self.render(context)
  File "C:\Python37\lib\site-packages\django\template\loader_tags.py", line 155, in render
    return compiled_parent._render(context)
  File "C:\Python37\lib\site-packages\django\template\base.py", line 167, in _render
    return self.nodelist.render(context)
  File "C:\Python37\lib\site-packages\django\template\base.py", line 943, in render
    bit = node.render_annotated(context)
  File "C:\Python37\lib\site-packages\django\template\base.py", line 910, in render_annotated
    return self.render(context)
  File "C:\Python37\lib\site-packages\django\template\loader_tags.py", line 67, in render
    result = block.nodelist.render(context)
  File "C:\Python37\lib\site-packages\django\template\base.py", line 943, in render
    bit = node.render_annotated(context)
  File "C:\Python37\lib\site-packages\django\template\base.py", line 910, in render_annotated
    return self.render(context)
  File "C:\Python37\lib\site-packages\django\template\loader_tags.py", line 67, in render
    result = block.nodelist.render(context)
  File "C:\Python37\lib\site-packages\django\template\base.py", line 943, in render
    bit = node.render_annotated(context)
  File "C:\Python37\lib\site-packages\django\template\base.py", line 910, in render_annotated
    return self.render(context)
  File "C:\Python37\lib\site-packages\django\template\defaulttags.py", line 447, in render
    url = reverse(view_name, args=args, kwargs=kwargs, current_app=current_app)
  File "C:\Python37\lib\site-packages\django\urls\base.py", line 90, in reverse
    return iri_to_uri(resolver._reverse_with_prefix(view, prefix, *args, **kwargs))
  File "C:\Python37\lib\site-packages\django\urls\resolvers.py", line 636, in _reverse_with_prefix
    raise NoReverseMatch(msg)
django.urls.exceptions.NoReverseMatch: Reverse for 'project_detail' with arguments '('',)' not found. 1 pattern(s) tried: ['project/edit/(?P<id>[0-9]+)/$']
2019-02-24 12:09:17,696 [Thread-6:12948] [django.request:118] [exception:handle_uncaught_exception] [ERROR]- Internal Server Error: /project/list/
Traceback (most recent call last):
  File "C:\Python37\lib\site-packages\django\core\handlers\exception.py", line 35, in inner
    response = get_response(request)
  File "C:\Python37\lib\site-packages\django\core\handlers\base.py", line 128, in _get_response
    response = self.process_exception_by_middleware(e, request)
  File "C:\Python37\lib\site-packages\django\core\handlers\base.py", line 126, in _get_response
    response = wrapped_callback(request, *callback_args, **callback_kwargs)
  File "C:\Python37\lib\site-packages\django\views\generic\base.py", line 69, in view
    return self.dispatch(request, *args, **kwargs)
  File "C:\Python37\lib\site-packages\django\views\generic\base.py", line 89, in dispatch
    return handler(request, *args, **kwargs)
  File "C:\Users\Administrator\PycharmProjects\TestPlatformWeb\apps\project\views.py", line 24, in get
    return render(request, 'project.html',{"obj_form":project_from})
  File "C:\Python37\lib\site-packages\django\shortcuts.py", line 36, in render
    content = loader.render_to_string(template_name, context, request, using=using)
  File "C:\Python37\lib\site-packages\django\template\loader.py", line 62, in render_to_string
    return template.render(context, request)
  File "C:\Python37\lib\site-packages\django\template\backends\django.py", line 61, in render
    return self.template.render(context)
  File "C:\Python37\lib\site-packages\django\template\base.py", line 175, in render
    return self._render(context)
  File "C:\Python37\lib\site-packages\django\template\base.py", line 167, in _render
    return self.nodelist.render(context)
  File "C:\Python37\lib\site-packages\django\template\base.py", line 943, in render
    bit = node.render_annotated(context)
  File "C:\Python37\lib\site-packages\django\template\base.py", line 910, in render_annotated
    return self.render(context)
  File "C:\Python37\lib\site-packages\django\template\loader_tags.py", line 155, in render
    return compiled_parent._render(context)
  File "C:\Python37\lib\site-packages\django\template\base.py", line 167, in _render
    return self.nodelist.render(context)
  File "C:\Python37\lib\site-packages\django\template\base.py", line 943, in render
    bit = node.render_annotated(context)
  File "C:\Python37\lib\site-packages\django\template\base.py", line 910, in render_annotated
    return self.render(context)
  File "C:\Python37\lib\site-packages\django\template\loader_tags.py", line 67, in render
    result = block.nodelist.render(context)
  File "C:\Python37\lib\site-packages\django\template\base.py", line 943, in render
    bit = node.render_annotated(context)
  File "C:\Python37\lib\site-packages\django\template\base.py", line 910, in render_annotated
    return self.render(context)
  File "C:\Python37\lib\site-packages\django\template\loader_tags.py", line 67, in render
    result = block.nodelist.render(context)
  File "C:\Python37\lib\site-packages\django\template\base.py", line 943, in render
    bit = node.render_annotated(context)
  File "C:\Python37\lib\site-packages\django\template\base.py", line 910, in render_annotated
    return self.render(context)
  File "C:\Python37\lib\site-packages\django\template\defaulttags.py", line 447, in render
    url = reverse(view_name, args=args, kwargs=kwargs, current_app=current_app)
  File "C:\Python37\lib\site-packages\django\urls\base.py", line 90, in reverse
    return iri_to_uri(resolver._reverse_with_prefix(view, prefix, *args, **kwargs))
  File "C:\Python37\lib\site-packages\django\urls\resolvers.py", line 636, in _reverse_with_prefix
    raise NoReverseMatch(msg)
django.urls.exceptions.NoReverseMatch: Reverse for 'project_detail' with arguments '('',)' not found. 1 pattern(s) tried: ['project/edit/\\(\\?P(?P<id>[^/]+)\\[0\\-9\\]\\+\\)/\\$/$']
2019-02-24 12:15:24,889 [Thread-30:9388] [django.request:93] [base:get_response] [WARNING]- Not Found: /favicon.ico
2019-02-24 12:16:14,086 [Thread-31:2816] [django.request:118] [exception:handle_uncaught_exception] [ERROR]- Internal Server Error: /project/list/
Traceback (most recent call last):
  File "C:\Python37\lib\site-packages\django\core\handlers\exception.py", line 35, in inner
    response = get_response(request)
  File "C:\Python37\lib\site-packages\django\core\handlers\base.py", line 128, in _get_response
    response = self.process_exception_by_middleware(e, request)
  File "C:\Python37\lib\site-packages\django\core\handlers\base.py", line 126, in _get_response
    response = wrapped_callback(request, *callback_args, **callback_kwargs)
  File "C:\Python37\lib\site-packages\django\views\generic\base.py", line 69, in view
    return self.dispatch(request, *args, **kwargs)
  File "C:\Python37\lib\site-packages\django\views\generic\base.py", line 89, in dispatch
    return handler(request, *args, **kwargs)
  File "C:\Users\Administrator\PycharmProjects\TestPlatformWeb\apps\project\views.py", line 24, in get
    return render(request, 'project.html',{"obj_form":project_from})
  File "C:\Python37\lib\site-packages\django\shortcuts.py", line 36, in render
    content = loader.render_to_string(template_name, context, request, using=using)
  File "C:\Python37\lib\site-packages\django\template\loader.py", line 62, in render_to_string
    return template.render(context, request)
  File "C:\Python37\lib\site-packages\django\template\backends\django.py", line 61, in render
    return self.template.render(context)
  File "C:\Python37\lib\site-packages\django\template\base.py", line 175, in render
    return self._render(context)
  File "C:\Python37\lib\site-packages\django\template\base.py", line 167, in _render
    return self.nodelist.render(context)
  File "C:\Python37\lib\site-packages\django\template\base.py", line 943, in render
    bit = node.render_annotated(context)
  File "C:\Python37\lib\site-packages\django\template\base.py", line 910, in render_annotated
    return self.render(context)
  File "C:\Python37\lib\site-packages\django\template\loader_tags.py", line 155, in render
    return compiled_parent._render(context)
  File "C:\Python37\lib\site-packages\django\template\base.py", line 167, in _render
    return self.nodelist.render(context)
  File "C:\Python37\lib\site-packages\django\template\base.py", line 943, in render
    bit = node.render_annotated(context)
  File "C:\Python37\lib\site-packages\django\template\base.py", line 910, in render_annotated
    return self.render(context)
  File "C:\Python37\lib\site-packages\django\template\loader_tags.py", line 67, in render
    result = block.nodelist.render(context)
  File "C:\Python37\lib\site-packages\django\template\base.py", line 943, in render
    bit = node.render_annotated(context)
  File "C:\Python37\lib\site-packages\django\template\base.py", line 910, in render_annotated
    return self.render(context)
  File "C:\Python37\lib\site-packages\django\template\loader_tags.py", line 67, in render
    result = block.nodelist.render(context)
  File "C:\Python37\lib\site-packages\django\template\base.py", line 943, in render
    bit = node.render_annotated(context)
  File "C:\Python37\lib\site-packages\django\template\base.py", line 910, in render_annotated
    return self.render(context)
  File "C:\Python37\lib\site-packages\django\template\defaulttags.py", line 447, in render
    url = reverse(view_name, args=args, kwargs=kwargs, current_app=current_app)
  File "C:\Python37\lib\site-packages\django\urls\base.py", line 90, in reverse
    return iri_to_uri(resolver._reverse_with_prefix(view, prefix, *args, **kwargs))
  File "C:\Python37\lib\site-packages\django\urls\resolvers.py", line 636, in _reverse_with_prefix
    raise NoReverseMatch(msg)
django.urls.exceptions.NoReverseMatch: Reverse for 'project_detail' with arguments '('',)' not found. 1 pattern(s) tried: ['project/edit/\\(\\?P(?P<id>[^/]+)\\[0\\-9\\]\\+\\)/\\$/$']
2019-02-24 12:16:14,581 [Thread-32:11808] [django.request:93] [base:get_response] [WARNING]- Not Found: /favicon.ico
2019-02-24 12:17:44,559 [Thread-54:8820] [django.request:93] [base:get_response] [WARNING]- Not Found: /favicon.ico
2019-02-24 12:18:50,228 [Thread-72:4944] [django.request:93] [base:get_response] [WARNING]- Not Found: /favicon.ico
2019-02-24 12:32:51,931 [Thread-21:12832] [django.request:93] [base:get_response] [WARNING]- Not Found: /favicon.ico
2019-02-24 12:34:07,497 [Thread-37:14152] [django.request:93] [base:get_response] [WARNING]- Not Found: /favicon.ico
2019-02-24 12:38:11,276 [Thread-22:1632] [django.request:118] [exception:handle_uncaught_exception] [ERROR]- Internal Server Error: /project/list/
Traceback (most recent call last):
  File "C:\Python37\lib\site-packages\django\core\handlers\exception.py", line 35, in inner
    response = get_response(request)
  File "C:\Python37\lib\site-packages\django\core\handlers\base.py", line 128, in _get_response
    response = self.process_exception_by_middleware(e, request)
  File "C:\Python37\lib\site-packages\django\core\handlers\base.py", line 126, in _get_response
    response = wrapped_callback(request, *callback_args, **callback_kwargs)
  File "C:\Python37\lib\site-packages\django\views\generic\base.py", line 69, in view
    return self.dispatch(request, *args, **kwargs)
  File "C:\Python37\lib\site-packages\django\views\generic\base.py", line 89, in dispatch
    return handler(request, *args, **kwargs)
  File "C:\Users\Administrator\PycharmProjects\TestPlatformWeb\apps\project\views.py", line 24, in get
    return render(request, 'project.html',{"obj_form":project_from})
  File "C:\Python37\lib\site-packages\django\shortcuts.py", line 36, in render
    content = loader.render_to_string(template_name, context, request, using=using)
  File "C:\Python37\lib\site-packages\django\template\loader.py", line 62, in render_to_string
    return template.render(context, request)
  File "C:\Python37\lib\site-packages\django\template\backends\django.py", line 61, in render
    return self.template.render(context)
  File "C:\Python37\lib\site-packages\django\template\base.py", line 175, in render
    return self._render(context)
  File "C:\Python37\lib\site-packages\django\template\base.py", line 167, in _render
    return self.nodelist.render(context)
  File "C:\Python37\lib\site-packages\django\template\base.py", line 943, in render
    bit = node.render_annotated(context)
  File "C:\Python37\lib\site-packages\django\template\base.py", line 910, in render_annotated
    return self.render(context)
  File "C:\Python37\lib\site-packages\django\template\loader_tags.py", line 155, in render
    return compiled_parent._render(context)
  File "C:\Python37\lib\site-packages\django\template\base.py", line 167, in _render
    return self.nodelist.render(context)
  File "C:\Python37\lib\site-packages\django\template\base.py", line 943, in render
    bit = node.render_annotated(context)
  File "C:\Python37\lib\site-packages\django\template\base.py", line 910, in render_annotated
    return self.render(context)
  File "C:\Python37\lib\site-packages\django\template\loader_tags.py", line 67, in render
    result = block.nodelist.render(context)
  File "C:\Python37\lib\site-packages\django\template\base.py", line 943, in render
    bit = node.render_annotated(context)
  File "C:\Python37\lib\site-packages\django\template\base.py", line 910, in render_annotated
    return self.render(context)
  File "C:\Python37\lib\site-packages\django\template\loader_tags.py", line 67, in render
    result = block.nodelist.render(context)
  File "C:\Python37\lib\site-packages\django\template\base.py", line 943, in render
    bit = node.render_annotated(context)
  File "C:\Python37\lib\site-packages\django\template\base.py", line 910, in render_annotated
    return self.render(context)
  File "C:\Python37\lib\site-packages\django\template\defaulttags.py", line 447, in render
    url = reverse(view_name, args=args, kwargs=kwargs, current_app=current_app)
  File "C:\Python37\lib\site-packages\django\urls\base.py", line 90, in reverse
    return iri_to_uri(resolver._reverse_with_prefix(view, prefix, *args, **kwargs))
  File "C:\Python37\lib\site-packages\django\urls\resolvers.py", line 636, in _reverse_with_prefix
    raise NoReverseMatch(msg)
django.urls.exceptions.NoReverseMatch: Reverse for 'project_detail' with arguments '('',)' not found. 1 pattern(s) tried: ['project/edit/(?P<id>[0-9]+)/$']
2019-02-24 12:38:11,863 [Thread-23:8200] [django.request:93] [base:get_response] [WARNING]- Not Found: /favicon.ico
2019-02-24 12:44:01,954 [Thread-41:5280] [django.request:93] [base:get_response] [WARNING]- Not Found: /favicon.ico
2019-02-24 12:49:27,868 [Thread-57:10924] [django.request:93] [base:get_response] [WARNING]- Not Found: /favicon.ico
2019-02-24 13:09:00,774 [Thread-6:872] [django.request:118] [exception:handle_uncaught_exception] [ERROR]- Internal Server Error: /project/list/
Traceback (most recent call last):
  File "C:\Python37\lib\site-packages\django\core\handlers\exception.py", line 35, in inner
    response = get_response(request)
  File "C:\Python37\lib\site-packages\django\core\handlers\base.py", line 128, in _get_response
    response = self.process_exception_by_middleware(e, request)
  File "C:\Python37\lib\site-packages\django\core\handlers\base.py", line 126, in _get_response
    response = wrapped_callback(request, *callback_args, **callback_kwargs)
  File "C:\Python37\lib\site-packages\django\views\generic\base.py", line 69, in view
    return self.dispatch(request, *args, **kwargs)
  File "C:\Python37\lib\site-packages\django\views\generic\base.py", line 89, in dispatch
    return handler(request, *args, **kwargs)
  File "C:\Users\Administrator\PycharmProjects\TestPlatformWeb\apps\project\views.py", line 24, in get
    return render(request, 'project.html',{"obj_form":project_from})
  File "C:\Python37\lib\site-packages\django\shortcuts.py", line 36, in render
    content = loader.render_to_string(template_name, context, request, using=using)
  File "C:\Python37\lib\site-packages\django\template\loader.py", line 61, in render_to_string
    template = get_template(template_name, using=using)
  File "C:\Python37\lib\site-packages\django\template\loader.py", line 15, in get_template
    return engine.get_template(template_name)
  File "C:\Python37\lib\site-packages\django\template\backends\django.py", line 34, in get_template
    return Template(self.engine.get_template(template_name), self)
  File "C:\Python37\lib\site-packages\django\template\engine.py", line 144, in get_template
    template, origin = self.find_template(template_name)
  File "C:\Python37\lib\site-packages\django\template\engine.py", line 126, in find_template
    template = loader.get_template(name, skip=skip)
  File "C:\Python37\lib\site-packages\django\template\loaders\base.py", line 30, in get_template
    contents, origin, origin.template_name, self.engine,
  File "C:\Python37\lib\site-packages\django\template\base.py", line 160, in __init__
    self.nodelist = self.compile_nodelist()
  File "C:\Python37\lib\site-packages\django\template\base.py", line 198, in compile_nodelist
    return parser.parse()
  File "C:\Python37\lib\site-packages\django\template\base.py", line 483, in parse
    raise self.error(token, e)
  File "C:\Python37\lib\site-packages\django\template\base.py", line 481, in parse
    compiled_result = compile_func(self, token)
  File "C:\Python37\lib\site-packages\django\template\loader_tags.py", line 290, in do_extends
    nodelist = parser.parse()
  File "C:\Python37\lib\site-packages\django\template\base.py", line 483, in parse
    raise self.error(token, e)
  File "C:\Python37\lib\site-packages\django\template\base.py", line 481, in parse
    compiled_result = compile_func(self, token)
  File "C:\Python37\lib\site-packages\django\template\loader_tags.py", line 233, in do_block
    nodelist = parser.parse(('endblock',))
  File "C:\Python37\lib\site-packages\django\template\base.py", line 483, in parse
    raise self.error(token, e)
  File "C:\Python37\lib\site-packages\django\template\base.py", line 481, in parse
    compiled_result = compile_func(self, token)
  File "C:\Python37\lib\site-packages\django\template\defaulttags.py", line 1363, in url
    viewname = parser.compile_filter(bits[1])
  File "C:\Python37\lib\site-packages\django\template\base.py", line 568, in compile_filter
    return FilterExpression(token, self)
  File "C:\Python37\lib\site-packages\django\template\base.py", line 668, in __init__
    "from '%s'" % (token[upto:], token))
django.template.exceptions.TemplateSyntaxError: Could not parse the remainder: ''project:project_detail' from ''project:project_detail'
2019-02-24 13:09:01,280 [Thread-7:1388] [django.request:93] [base:get_response] [WARNING]- Not Found: /favicon.ico
2019-02-24 13:09:30,214 [Thread-10:4856] [django.request:118] [exception:handle_uncaught_exception] [ERROR]- Internal Server Error: /project/edit/
Traceback (most recent call last):
  File "C:\Python37\lib\site-packages\django\core\handlers\exception.py", line 35, in inner
    response = get_response(request)
  File "C:\Python37\lib\site-packages\django\core\handlers\base.py", line 128, in _get_response
    response = self.process_exception_by_middleware(e, request)
  File "C:\Python37\lib\site-packages\django\core\handlers\base.py", line 126, in _get_response
    response = wrapped_callback(request, *callback_args, **callback_kwargs)
  File "C:\Python37\lib\site-packages\django\views\decorators\csrf.py", line 54, in wrapped_view
    return view_func(*args, **kwargs)
  File "C:\Python37\lib\site-packages\django\views\generic\base.py", line 69, in view
    return self.dispatch(request, *args, **kwargs)
  File "C:\Python37\lib\site-packages\rest_framework\views.py", line 495, in dispatch
    response = self.handle_exception(exc)
  File "C:\Python37\lib\site-packages\rest_framework\views.py", line 455, in handle_exception
    self.raise_uncaught_exception(exc)
  File "C:\Python37\lib\site-packages\rest_framework\views.py", line 492, in dispatch
    response = handler(request, *args, **kwargs)
TypeError: get() missing 1 required positional argument: 'id'
